Workbook

Sheet Summary
A1: Personal Evolution Intelligence
A2: Exported on 16/10/2026 at 10:20, period from 19/07/2026 to 16/10/2026
A4: Key indicators
A5: Days in the period | B5: =COUNTA(Daily!$A$2:$A$91) -> 90
A6: Days filled in | B6: =COUNTIFS(Daily!$C$2:$C$91,"Yes") -> 82
A7: Consistency | B7: =IFERROR(B6/B5,0) -> 0.91111111
A8: Intentions set | B8: =COUNTA(Intentions!$A$2:$A$365) -> 364
A9: Intentions reviewed | B9: =COUNTIFS(Intentions!$H$2:$H$365,"<>Planned",Intentions!$A$2:$A$365,"<>") -> 353
A10: Intentions done (fully or partly) | B10: =COUNTIFS(Intentions!$H$2:$H$365,"Done")+COUNTIFS(Intentions!$H$2:$H$365,"Partial") -> 168
A11: Completion rate | B11: =IFERROR(SUM(Intentions!$K$2:$K$365)/B9,"") -> 0.44617564 | C11: Done = 1, Partial = 0.5, other statuses = 0
A12: Total tracked time (hours) | B12: =SUM(Activities!$F$2:$F$190)/60 -> 164.63333
A13: Average tracked time per filled in day (minutes) | B13: =IFERROR(SUM(Activities!$F$2:$F$190)/B6,"") -> 120.46341
A14: Average gap between planned and actual time (minutes) | B14: =IFERROR(AVERAGE(Intentions!$J$2:$J$365),"") -> 5.0178571
A15: Average sleep (hours) | B15: =IFERROR(AVERAGE(Daily!$Q$2:$Q$91),"") -> 6.9536585
A16: Average energy (out of 5) | B16: =IFERROR(AVERAGE(Daily!$S$2:$S$91),"") -> 3.0365854
A17: Average mood (out of 5) | B17: =IFERROR(AVERAGE(Daily!$U$2:$U$91),"") -> 3.2195122
A18: Written reflections | B18: =COUNTA(Reflections!$D$2:$D$70) -> 69
A19: Most hours in one week | B19: =MAX(Weekly!$I$2:$I$15) -> 20.733333
A20: Days filled in the same day | B20: =COUNTIFS(Daily!$AA$2:$AA$91,"Filled in the same day") -> 72
A21: Days caught up later | B21: =COUNTIFS(Daily!$AA$2:$AA$91,"Caught up later") -> 9
A22: Days forgotten (deadline passed) | B22: =COUNTIFS(Daily!$AA$2:$AA$91,"Forgotten (locked)") -> 7
A23: Same day forgetting rate | B23: =IFERROR((B21+B22)/(B20+B21+B22),"") -> 0.18181818
A24: Average catch up delay (days) | B24: =IFERROR(AVERAGEIFS(Daily!$AB$2:$AB$91,Daily!$AA$2:$AA$91,"Caught up later"),"") -> 2.2222222
A27: By life dimension
A28: Dimension | B28: Hours | C28: Intentions | D28: Completion rate | E28: Share of time
A29: Spiritual | B29: =SUMIFS(Activities!$F$2:$F$190,Activities!$C$2:$C$190,$A29)/60 -> 12.866667 | C29: =COUNTIFS(Intentions!$C$2:$C$365,$A29) -> 60 | D29: =IFERROR(SUMIFS(Intentions!$K$2:$K$365,Intentions!$C$2:$C$365,$A29)/COUNTIFS(Intentions!$C$2:$C$365,$A29,Intentions!$H$2:$H$365,"<>Planned"),"") -> 0.69491525 | E29: =IFERROR(B29/$B$12,"") -> 0.078153472
A30: Physical | B30: =SUMIFS(Activities!$F$2:$F$190,Activities!$C$2:$C$190,$A30)/60 -> 11.033333 | C30: =COUNTIFS(Intentions!$C$2:$C$365,$A30) -> 53 | D30: =IFERROR(SUMIFS(Intentions!$K$2:$K$365,Intentions!$C$2:$C$365,$A30)/COUNTIFS(Intentions!$C$2:$C$365,$A30,Intentions!$H$2:$H$365,"<>Planned"),"") -> 0.38235294 | E30: =IFERROR(B30/$B$12,"") -> 0.067017615
A31: Studies | B31: =SUMIFS(Activities!$F$2:$F$190,Activities!$C$2:$C$190,$A31)/60 -> 84.55 | C31: =COUNTIFS(Intentions!$C$2:$C$365,$A31) -> 138 | D31: =IFERROR(SUMIFS(Intentions!$K$2:$K$365,Intentions!$C$2:$C$365,$A31)/COUNTIFS(Intentions!$C$2:$C$365,$A31,Intentions!$H$2:$H$365,"<>Planned"),"") -> 0.41111111 | E31: =IFERROR(B31/$B$12,"") -> 0.5135655
A32: Professional | B32: =SUMIFS(Activities!$F$2:$F$190,Activities!$C$2:$C$190,$A32)/60 -> 11.483333 | C32: =COUNTIFS(Intentions!$C$2:$C$365,$A32) -> 44 | D32: =IFERROR(SUMIFS(Intentions!$K$2:$K$365,Intentions!$C$2:$C$365,$A32)/COUNTIFS(Intentions!$C$2:$C$365,$A32,Intentions!$H$2:$H$365,"<>Planned"),"") -> 0.23255814 | E32: =IFERROR(B32/$B$12,"") -> 0.069750962
A33: Personal | B33: =SUMIFS(Activities!$F$2:$F$190,Activities!$C$2:$C$190,$A33)/60 -> 5.3666667 | C33: =COUNTIFS(Intentions!$C$2:$C$365,$A33) -> 26 | D33: =IFERROR(SUMIFS(Intentions!$K$2:$K$365,Intentions!$C$2:$C$365,$A33)/COUNTIFS(Intentions!$C$2:$C$365,$A33,Intentions!$H$2:$H$365,"<>Planned"),"") -> 0.52083333 | E33: =IFERROR(B33/$B$12,"") -> 0.032597692
A34: Relationships | B34: =SUMIFS(Activities!$F$2:$F$190,Activities!$C$2:$C$190,$A34)/60 -> 5.6 | C34: =COUNTIFS(Intentions!$C$2:$C$365,$A34) -> 25 | D34: =IFERROR(SUMIFS(Intentions!$K$2:$K$365,Intentions!$C$2:$C$365,$A34)/COUNTIFS(Intentions!$C$2:$C$365,$A34,Intentions!$H$2:$H$365,"<>Planned"),"") -> 0.63043478 | E34: =IFERROR(B34/$B$12,"") -> 0.034014983
A35: Leisure and creativity | B35: =SUMIFS(Activities!$F$2:$F$190,Activities!$C$2:$C$190,$A35)/60 -> 33.733333 | C35: =COUNTIFS(Intentions!$C$2:$C$365,$A35) -> 18 | D35: =IFERROR(SUMIFS(Intentions!$K$2:$K$365,Intentions!$C$2:$C$365,$A35)/COUNTIFS(Intentions!$C$2:$C$365,$A35,Intentions!$H$2:$H$365,"<>Planned"),"") -> 0.25 | E35: =IFERROR(B35/$B$12,"") -> 0.20489978
A38: Workbook contents
A39: Daily | B39: One row per day: reported indicators and totals computed by formulas.
A40: Weekly, Monthly | B40: Weekly and monthly aggregates (formulas).
A41: Intentions, Activities, Reflections | B41: Raw data for the period. Editable: the indicators recalculate.
A42: Calibration, Dropped | B42: Planned versus actual time, goals not done and reasons (formulas).
A43: Goals, Skills, Assessments | B43: Progress of goals and skills.
A44: Analyses | B44: Trends, associations, unusual days, recommendations (values computed by PEI).
A45: Decisions, Experiments, Relationships, Media | B45: Log of decisions, experiments, relationships and files.

Sheet Daily
A1: Date | B1: Day | C1: Filled in | D1: Intentions | E1: Reviewed | F1: Done | G1: Completion rate | H1: Planned time (min) | I1: Actual time (min) | J1: Spiritual (min) | K1: Physical (min) | L1: Studies (min) | M1: Professional (min) | N1: Personal (min) | O1: Relationships (min) | P1: Leisure and creativity (min) | Q1: Sleep (h) | R1: Sleep quality | S1: Energy | T1: Motivation | U1: Mood | V1: Stress | W1: Screen (min) | X1: Steps | Y1: Water (l) | Z1: Reflections | AA1: Entries | AB1: Entry delay (days) | AC1: Highlight
A2: 46222 | B2: =INDEX({"Monday","Tuesday","Wednesday","Thursday","Friday","Saturday","Sunday"},WEEKDAY($A2,2)) -> Sunday | C2: Yes | D2: =COUNTIFS(Intentions!$B$2:$B$365,$A2) -> 2 | E2: =COUNTIFS(Intentions!$B$2:$B$365,$A2,Intentions!$H$2:$H$365,"<>Planned") -> 2 | F2: =COUNTIFS(Intentions!$B$2:$B$365,$A2,Intentions!$H$2:$H$365,"Done")+COUNTIFS(Intentions!$B$2:$B$365,$A2,Intentions!$H$2:$H$365,"Partial") -> 2 | G2: =IF(E2=0,"",SUMIFS(Intentions!$K$2:$K$365,Intentions!$B$2:$B$365,$A2)/E2) -> 1 | H2: =SUMIFS(Intentions!$G$2:$G$365,Intentions!$B$2:$B$365,$A2) -> 75 | I2: =SUMIFS(Activities!$F$2:$F$190,Activities!$B$2:$B$190,$A2) -> 217 | J2: =SUMIFS(Activities!$F$2:$F$190,Activities!$B$2:$B$190,$A2,Activities!$C$2:$C$190,"Spiritual") -> 21 | K2: =SUMIFS(Activities!$F$2:$F$190,Activities!$B$2:$B$190,$A2,Activities!$C$2:$C$190,"Physical") -> 0 | L2: =SUMIFS(Activities!$F$2:$F$190,Activities!$B$2:$B$190,$A2,Activities!$C$2:$C$190,"Studies") -> 106 | M2: =SUMIFS(Activities!$F$2:$F$190,Activities!$B$2:$B$190,$A2,Activities!$C$2:$C$190,"Professional") -> 0 | N2: =SUMIFS(Activities!$F$2:$F$190,Activities!$B$2:$B$190,$A2,Activities!$C$2:$C$190,"Personal") -> 0 | O2: =SUMIFS(Activities!$F$2:$F$190,Activities!$B$2:$B$190,$A2,Activities!$C$2:$C$190,"Relationships") -> 0 | P2: =SUMIFS(Activities!$F$2:$F$190,Activities!$B$2:$B$190,$A2,Activities!$C$2:$C$190,"Leisure and creativity") -> 90 | Q2: 7.8 | S2: 4 | T2: 4 | U2: 5 | V2: 4 | W2: 153 | X2: 1773 | Y2: 2.2 | Z2: =COUNTIFS(Reflections!$A$2:$A$70,$A2) -> 1 | AA2: Caught up later | AB2: 3
A3: 46223 | B3: =INDEX({"Monday","Tuesday","Wednesday","Thursday","Friday","Saturday","Sunday"},WEEKDAY($A3,2)) -> Monday | C3: Yes | D3: =COUNTIFS(Intentions!$B$2:$B$365,$A3) -> 2 | E3: =COUNTIFS(Intentions!$B$2:$B$365,$A3,Intentions!$H$2:$H$365,"<>Planned") -> 2 | F3: =COUNTIFS(Intentions!$B$2:$B$365,$A3,Intentions!$H$2:$H$365,"Done")+COUNTIFS(Intentions!$B$2:$B$365,$A3,Intentions!$H$2:$H$365,"Partial") -> 1 | G3: =IF(E3=0,"",SUMIFS(Intentions!$K$2:$K$365,Intentions!$B$2:$B$365,$A3)/E3) -> 0.5 | H3: =SUMIFS(Intentions!$G$2:$G$365,Intentions!$B$2:$B$365,$A3) -> 60 | I3: =SUMIFS(Activities!$F$2:$F$190,Activities!$B$2:$B$190,$A3) -> 41 | J3: =SUMIFS(Activities!$F$2:$F$190,Activities!$B$2:$B$190,$A3,Activities!$C$2:$C$190,"Spiritual") -> 0 | K3: =SUMIFS(Activities!$F$2:$F$190,Activities!$B$2:$B$190,$A3,Activities!$C$2:$C$190,"Physical") -> 41 | L3: =SUMIFS(Activities!$F$2:$F$190,Activities!$B$2:$B$190,$A3,Activities!$C$2:$C$190,"Studies") -> 0 | M3: =SUMIFS(Activities!$F$2:$F$190,Activities!$B$2:$B$190,$A3,Activities!$C$2:$C$190,"Professional") -> 0 | N3: =SUMIFS(Activities!$F$2:$F$190,Activities!$B$2:$B$190,$A3,Activities!$C$2:$C$190,"Personal") -> 0 | O3: =SUMIFS(Activities!$F$2:$F$190,Activities!$B$2:$B$190,$A3,Activities!$C$2:$C$190,"Relationships") -> 0 | P3: =SUMIFS(Activities!$F$2:$F$190,Activities!$B$2:$B$190,$A3,Activities!$C$2:$C$190,"Leisure and creativity") -> 0 | Q3: 8 | S3: 4 | T3: 3 | U3: 3 | V3: 2 | W3: 122 | X3: 3129 | Y3: 1.2 | Z3: =COUNTIFS(Reflections!$A$2:$A$70,$A3) -> 2 | AA3: Filled in the same day | AB3: 0
A4: 46224 | B4: =INDEX({"Monday","Tuesday","Wednesday","Thursday","Friday","Saturday","Sunday"},WEEKDAY($A4,2)) -> Tuesday | C4: Yes | D4: =COUNTIFS(Intentions!$B$2:$B$365,$A4) -> 4 | E4: =COUNTIFS(Intentions!$B$2:$B$365,$A4,Intentions!$H$2:$H$365,"<>Planned") -> 4 | F4: =COUNTIFS(Intentions!$B$2:$B$365,$A4,Intentions!$H$2:$H$365,"Done")+COUNTIFS(Intentions!$B$2:$B$365,$A4,Intentions!$H$2:$H$365,"Partial") -> 4 | G4: =IF(E4=0,"",SUMIFS(Intentions!$K$2:$K$365,Intentions!$B$2:$B$365,$A4)/E4) -> 1 | H4: =SUMIFS(Intentions!$G$2:$G$365,Intentions!$B$2:$B$365,$A4) -> 245 | I4: =SUMIFS(Activities!$F$2:$F$190,Activities!$B$2:$B$190,$A4) -> 284 | J4: =SUMIFS(Activities!$F$2:$F$190,Activities!$B$2:$B$190,$A4,Activities!$C$2:$C$190,"Spiritual") -> 16 | K4: =SUMIFS(Activities!$F$2:$F$190,Activities!$B$2:$B$190,$A4,Activities!$C$2:$C$190,"Physical") -> 0 | L4: =SUMIFS(Activities!$F$2:$F$190,Activities!$B$2:$B$190,$A4,Activities!$C$2:$C$190,"Studies") -> 268 | M4: =SUMIFS(Activities!$F$2:$F$190,Activities!$B$2:$B$190,$A4,Activities!$C$2:$C$190,"Professional") -> 0 | N4: =SUMIFS(Activities!$F$2:$F$190,Activities!$B$2:$B$190,$A4,Activities!$C$2:$C$190,"Personal") -> 0 | O4: =SUMIFS(Activities!$F$2:$F$190,Activities!$B$2:$B$190,$A4,Activities!$C$2:$C$190,"Relationships") -> 0 | P4: =SUMIFS(Activities!$F$2:$F$190,Activities!$B$2:$B$190,$A4,Activities!$C$2:$C$190,"Leisure and creativity") -> 0 | Q4: 7.5 | S4: 4 | T4: 5 | U4: 3 | V4: 3 | W4: 124 | X4: 5169 | Y4: 2.2 | Z4: =COUNTIFS(Reflections!$A$2:$A$70,$A4) -> 1 | AA4: Filled in the same day | AB4: 0
A5: 46225 | B5: =INDEX({"Monday","Tuesday","Wednesday","Thursday","Friday","Saturday","Sunday"},WEEKDAY($A5,2)) -> Wednesday | C5: Yes | D5: =COUNTIFS(Intentions!$B$2:$B$365,$A5) -> 4 | E5: =COUNTIFS(Intentions!$B$2:$B$365,$A5,Intentions!$H$2:$H$365,"<>Planned") -> 4 | F5: =COUNTIFS(Intentions!$B$2:$B$365,$A5,Intentions!$H$2:$H$365,"Done")+COUNTIFS(Intentions!$B$2:$B$365,$A5,Intentions!$H$2:$H$365,"Partial") -> 2 | G5: =IF(E5=0,"",SUMIFS(Intentions!$K$2:$K$365,Intentions!$B$2:$B$365,$A5)/E5) -> 0.25 | H5: =SUMIFS(Intentions!$G$2:$G$365,Intentions!$B$2:$B$365,$A5) -> 185 | I5: =SUMIFS(Activities!$F$2:$F$190,Activities!$B$2:$B$190,$A5) -> 54 | J5: =SUMIFS(Activities!$F$2:$F$190,Activities!$B$2:$B$190,$A5,Activities!$C$2:$C$190,"Spiritual") -> 0 | K5: =SUMIFS(Activities!$F$2:$F$190,Activities!$B$2:$B$190,$A5,Activities!$C$2:$C$190,"Physical") -> 0 | L5: =SUMIFS(Activities!$F$2:$F$190,Activities!$B$2:$B$190,$A5,Activities!$C$2:$C$190,"Studies") -> 0 | M5: =SUMIFS(Activities!$F$2:$F$190,Activities!$B$2:$B$190,$A5,Activities!$C$2:$C$190,"Professional") -> 37 | N5: =SUMIFS(Activities!$F$2:$F$190,Activities!$B$2:$B$190,$A5,Activities!$C$2:$C$190,"Personal") -> 0 | O5: =SUMIFS(Activities!$F$2:$F$190,Activities!$B$2:$B$190,$A5,Activities!$C$2:$C$190,"Relationships") -> 17 | P5: =SUMIFS(Activities!$F$2:$F$190,Activities!$B$2:$B$190,$A5,Activities!$C$2:$C$190,"Leisure and creativity") -> 0 | Q5: 7 | S5: 3 | T5: 3 | U5: 3 | V5: 1 | W5: 310 | X5: 5755 | Y5: 1.6 | Z5: =COUNTIFS(Reflections!$A$2:$A$70,$A5) -> 0 | AA5: Filled in the same day | AB5: 0
A6: 46226 | B6: =INDEX({"Monday","Tuesday","Wednesday","Thursday","Friday","Saturday","Sunday"},WEEKDAY($A6,2)) -> Thursday | C6: Yes | D6: =COUNTIFS(Intentions!$B$2:$B$365,$A6) -> 6 | E6: =COUNTIFS(Intentions!$B$2:$B$365,$A6,Intentions!$H$2:$H$365,"<>Planned") -> 6 | F6: =COUNTIFS(Intentions!$B$2:$B$365,$A6,Intentions!$H$2:$H$365,"Done")+COUNTIFS(Intentions!$B$2:$B$365,$A6,Intentions!$H$2:$H$365,"Partial") -> 2 | G6: =IF(E6=0,"",SUMIFS(Intentions!$K$2:$K$365,Intentions!$B$2:$B$365,$A6)/E6) -> 0.33333333 | H6: =SUMIFS(Intentions!$G$2:$G$365,Intentions!$B$2:$B$365,$A6) -> 195 | I6: =SUMIFS(Activities!$F$2:$F$190,Activities!$B$2:$B$190,$A6) -> 127 | J6: =SUMIFS(Activities!$F$2:$F$190,Activities!$B$2:$B$190,$A6,Activities!$C$2:$C$190,"Spiritual") -> 37 | K6: =SUMIFS(Activities!$F$2:$F$190,Activities!$B$2:$B$190,$A6,Activities!$C$2:$C$190,"Physical") -> 0 | L6: =SUMIFS(Activities!$F$2:$F$190,Activities!$B$2:$B$190,$A6,Activities!$C$2:$C$190,"Studies") -> 0 | M6: =SUMIFS(Activities!$F$2:$F$190,Activities!$B$2:$B$190,$A6,Activities!$C$2:$C$190,"Professional") -> 0 | N6: =SUMIFS(Activities!$F$2:$F$190,Activities!$B$2:$B$190,$A6,Activities!$C$2:$C$190,"Personal") -> 0 | O6: =SUMIFS(Activities!$F$2:$F$190,Activities!$B$2:$B$190,$A6,Activities!$C$2:$C$190,"Relationships") -> 0 | P6: =SUMIFS(Activities!$F$2:$F$190,Activities!$B$2:$B$190,$A6,Activities!$C$2:$C$190,"Leisure and creativity") -> 90 | Q6: 8.5 | S6: 4 | T6: 4 | U6: 4 | V6: 1 | W6: 137 | X6: 8712 | Y6: 1.2 | Z6: =COUNTIFS(Reflections!$A$2:$A$70,$A6) -> 2 | AA6: Filled in the same day | AB6: 0
A7: 46227 | B7: =INDEX({"Monday","Tuesday","Wednesday","Thursday","Friday","Saturday","Sunday"},WEEKDAY($A7,2)) -> Friday | C7: Yes | D7: =COUNTIFS(Intentions!$B$2:$B$365,$A7) -> 7 | E7: =COUNTIFS(Intentions!$B$2:$B$365,$A7,Intentions!$H$2:$H$365,"<>Planned") -> 7 | F7: =COUNTIFS(Intentions!$B$2:$B$365,$A7,Intentions!$H$2:$H$365,"Done")+COUNTIFS(Intentions!$B$2:$B$365,$A7,Intentions!$H$2:$H$365,"Partial") -> 4 | G7: =IF(E7=0,"",SUMIFS(Intentions!$K$2:$K$365,Intentions!$B$2:$B$365,$A7)/E7) -> 0.57142857 | H7: =SUMIFS(Intentions!$G$2:$G$365,Intentions!$B$2:$B$365,$A7) -> 270 | I7: =SUMIFS(Activities!$F$2:$F$190,Activities!$B$2:$B$190,$A7) -> 236 | J7: =SUMIFS(Activities!$F$2:$F$190,Activities!$B$2:$B$190,$A7,Activities!$C$2:$C$190,"Spiritual") -> 0 | K7: =SUMIFS(Activities!$F$2:$F$190,Activities!$B$2:$B$190,$A7,Activities!$C$2:$C$190,"Physical") -> 77 | L7: =SUMIFS(Activities!$F$2:$F$190,Activities!$B$2:$B$190,$A7,Activities!$C$2:$C$190,"Studies") -> 99 | M7: =SUMIFS(Activities!$F$2:$F$190,Activities!$B$2:$B$190,$A7,Activities!$C$2:$C$190,"Professional") -> 0 | N7: =SUMIFS(Activities!$F$2:$F$190,Activities!$B$2:$B$190,$A7,Activities!$C$2:$C$190,"Personal") -> 0 | O7: =SUMIFS(Activities!$F$2:$F$190,Activities!$B$2:$B$190,$A7,Activities!$C$2:$C$190,"Relationships") -> 0 | P7: =SUMIFS(Activities!$F$2:$F$190,Activities!$B$2:$B$190,$A7,Activities!$C$2:$C$190,"Leisure and creativity") -> 60 | Q7: 6.3 | S7: 3 | T7: 3 | U7: 3 | V7: 5 | W7: 98 | X7: 8238 | Y7: 1.7 | Z7: =COUNTIFS(Reflections!$A$2:$A$70,$A7) -> 0 | AA7: Filled in the same day | AB7: 0
A8: 46228 | B8: =INDEX({"Monday","Tuesday","Wednesday","Thursday","Friday","Saturday","Sunday"},WEEKDAY($A8,2)) -> Saturday | C8: Yes | D8: =COUNTIFS(Intentions!$B$2:$B$365,$A8) -> 6 | E8: =COUNTIFS(Intentions!$B$2:$B$365,$A8,Intentions!$H$2:$H$365,"<>Planned") -> 6 | F8: =COUNTIFS(Intentions!$B$2:$B$365,$A8,Intentions!$H$2:$H$365,"Done")+COUNTIFS(Intentions!$B$2:$B$365,$A8,Intentions!$H$2:$H$365,"Partial") -> 4 | G8: =IF(E8=0,"",SUMIFS(Intentions!$K$2:$K$365,Intentions!$B$2:$B$365,$A8)/E8) -> 0.58333333 | H8: =SUMIFS(Intentions!$G$2:$G$365,Intentions!$B$2:$B$365,$A8) -> 230 | I8: =SUMIFS(Activities!$F$2:$F$190,Activities!$B$2:$B$190,$A8) -> 173 | J8: =SUMIFS(Activities!$F$2:$F$190,Activities!$B$2:$B$190,$A8,Activities!$C$2:$C$190,"Spiritual") -> 0 | K8: =SUMIFS(Activities!$F$2:$F$190,Activities!$B$2:$B$190,$A8,Activities!$C$2:$C$190,"Physical") -> 0 | L8: =SUMIFS(Activities!$F$2:$F$190,Activities!$B$2:$B$190,$A8,Activities!$C$2:$C$190,"Studies") -> 43 | M8: =SUMIFS(Activities!$F$2:$F$190,Activities!$B$2:$B$190,$A8,Activities!$C$2:$C$190,"Professional") -> 71 | N8: =SUMIFS(Activities!$F$2:$F$190,Activities!$B$2:$B$190,$A8,Activities!$C$2:$C$190,"Personal") -> 39 | O8: =SUMIFS(Activities!$F$2:$F$190,Activities!$B$2:$B$190,$A8,Activities!$C$2:$C$190,"Relationships") -> 20 | P8: =SUMIFS(Activities!$F$2:$F$190,Activities!$B$2:$B$190,$A8,Activities!$C$2:$C$190,"Leisure and creativity") -> 0 | Q8: 6.8 | S8: 2 | T8: 1 | U8: 3 | V8: 4 | W8: 193 | X8: 8572 | Y8: 1.8 | Z8: =COUNTIFS(Reflections!$A$2:$A$70,$A8) -> 2 | AA8: Caught up later | AB8: 4
A9: 46229 | B9: =INDEX({"Monday","Tuesday","Wednesday","Thursday","Friday","Saturday","Sunday"},WEEKDAY($A9,2)) -> Sunday | C9: No | D9: =COUNTIFS(Intentions!$B$2:$B$365,$A9) -> 0 | E9: =COUNTIFS(Intentions!$B$2:$B$365,$A9,Intentions!$H$2:$H$365,"<>Planned") -> 0 | F9: =COUNTIFS(Intentions!$B$2:$B$365,$A9,Intentions!$H$2:$H$365,"Done")+COUNTIFS(Intentions!$B$2:$B$365,$A9,Intentions!$H$2:$H$365,"Partial") -> 0 | G9: =IF(E9=0,"",SUMIFS(Intentions!$K$2:$K$365,Intentions!$B$2:$B$365,$A9)/E9) | H9: =SUMIFS(Intentions!$G$2:$G$365,Intentions!$B$2:$B$365,$A9) -> 0 | I9: =SUMIFS(Activities!$F$2:$F$190,Activities!$B$2:$B$190,$A9) -> 0 | J9: =SUMIFS(Activities!$F$2:$F$190,Activities!$B$2:$B$190,$A9,Activities!$C$2:$C$190,"Spiritual") -> 0 | K9: =SUMIFS(Activities!$F$2:$F$190,Activities!$B$2:$B$190,$A9,Activities!$C$2:$C$190,"Physical") -> 0 | L9: =SUMIFS(Activities!$F$2:$F$190,Activities!$B$2:$B$190,$A9,Activities!$C$2:$C$190,"Studies") -> 0 | M9: =SUMIFS(Activities!$F$2:$F$190,Activities!$B$2:$B$190,$A9,Activities!$C$2:$C$190,"Professional") -> 0 | N9: =SUMIFS(Activities!$F$2:$F$190,Activities!$B$2:$B$190,$A9,Activities!$C$2:$C$190,"Personal") -> 0 | O9: =SUMIFS(Activities!$F$2:$F$190,Activities!$B$2:$B$190,$A9,Activities!$C$2:$C$190,"Relationships") -> 0 | P9: =SUMIFS(Activities!$F$2:$F$190,Activities!$B$2:$B$190,$A9,Activities!$C$2:$C$190,"Leisure and creativity") -> 0 | Z9: =COUNTIFS(Reflections!$A$2:$A$70,$A9) -> 0 | AA9: Forgotten (locked)
A10: 46230 | B10: =INDEX({"Monday","Tuesday","Wednesday","Thursday","Friday","Saturday","Sunday"},WEEKDAY($A10,2)) -> Monday | C10: Yes | D10: =COUNTIFS(Intentions!$B$2:$B$365,$A10) -> 2 | E10: =COUNTIFS(Intentions!$B$2:$B$365,$A10,Intentions!$H$2:$H$365,"<>Planned") -> 2 | F10: =COUNTIFS(Intentions!$B$2:$B$365,$A10,Intentions!$H$2:$H$365,"Done")+COUNTIFS(Intentions!$B$2:$B$365,$A10,Intentions!$H$2:$H$365,"Partial") -> 0 | G10: =IF(E10=0,"",SUMIFS(Intentions!$K$2:$K$365,Intentions!$B$2:$B$365,$A10)/E10) -> 0 | H10: =SUMIFS(Intentions!$G$2:$G$365,Intentions!$B$2:$B$365,$A10) -> 100 | I10: =SUMIFS(Activities!$F$2:$F$190,Activities!$B$2:$B$190,$A10) -> 0 | J10: =SUMIFS(Activities!$F$2:$F$190,Activities!$B$2:$B$190,$A10,Activities!$C$2:$C$190,"Spiritual") -> 0 | K10: =SUMIFS(Activities!$F$2:$F$190,Activities!$B$2:$B$190,$A10,Activities!$C$2:$C$190,"Physical") -> 0 | L10: =SUMIFS(Activities!$F$2:$F$190,Activities!$B$2:$B$190,$A10,Activities!$C$2:$C$190,"Studies") -> 0 | M10: =SUMIFS(Activities!$F$2:$F$190,Activities!$B$2:$B$190,$A10,Activities!$C$2:$C$190,"Professional") -> 0 | N10: =SUMIFS(Activities!$F$2:$F$190,Activities!$B$2:$B$190,$A10,Activities!$C$2:$C$190,"Personal") -> 0 | O10: =SUMIFS(Activities!$F$2:$F$190,Activities!$B$2:$B$190,$A10,Activities!$C$2:$C$190,"Relationships") -> 0 | P10: =SUMIFS(Activities!$F$2:$F$190,Activities!$B$2:$B$190,$A10,Activities!$C$2:$C$190,"Leisure and creativity") -> 0 | Q10: 8 | S10: 3 | T10: 4 | U10: 3 | V10: 2 | W10: 228 | X10: 7546 | Y10: 1.5 | Z10: =COUNTIFS(Reflections!$A$2:$A$70,$A10) -> 1 | AA10: Filled in the same day | AB10: 0
A11: 46231 | B11: =INDEX({"Monday","Tuesday","Wednesday","Thursday","Friday","Saturday","Sunday"},WEEKDAY($A11,2)) -> Tuesday | C11: Yes | D11: =COUNTIFS(Intentions!$B$2:$B$365,$A11) -> 2 | E11: =COUNTIFS(Intentions!$B$2:$B$365,$A11,Intentions!$H$2:$H$365,"<>Planned") -> 2 | F11: =COUNTIFS(Intentions!$B$2:$B$365,$A11,Intentions!$H$2:$H$365,"Done")+COUNTIFS(Intentions!$B$2:$B$365,$A11,Intentions!$H$2:$H$365,"Partial") -> 2 | G11: =IF(E11=0,"",SUMIFS(Intentions!$K$2:$K$365,Intentions!$B$2:$B$365,$A11)/E11) -> 1 | H11: =SUMIFS(Intentions!$G$2:$G$365,Intentions!$B$2:$B$365,$A11) -> 120 | I11: =SUMIFS(Activities!$F$2:$F$190,Activities!$B$2:$B$190,$A11) -> 214 | J11: =SUMIFS(Activities!$F$2:$F$190,Activities!$B$2:$B$190,$A11,Activities!$C$2:$C$190,"Spiritual") -> 0 | K11: =SUMIFS(Activities!$F$2:$F$190,Activities!$B$2:$B$190,$A11,Activities!$C$2:$C$190,"Physical") -> 0 | L11: =SUMIFS(Activities!$F$2:$F$190,Activities!$B$2:$B$190,$A11,Activities!$C$2:$C$190,"Studies") -> 124 | M11: =SUMIFS(Activities!$F$2:$F$190,Activities!$B$2:$B$190,$A11,Activities!$C$2:$C$190,"Professional") -> 0 | N11: =SUMIFS(Activities!$F$2:$F$190,Activities!$B$2:$B$190,$A11,Activities!$C$2:$C$190,"Personal") -> 0 | O11: =SUMIFS(Activities!$F$2:$F$190,Activities!$B$2:$B$190,$A11,Activities!$C$2:$C$190,"Relationships") -> 0 | P11: =SUMIFS(Activities!$F$2:$F$190,Activities!$B$2:$B$190,$A11,Activities!$C$2:$C$190,"Leisure and creativity") -> 90 | Q11: 5.9 | S11: 4 | T11: 5 | U11: 4 | V11: 1 | W11: 227 | X11: 4672 | Y11: 1.8 | Z11: =COUNTIFS(Reflections!$A$2:$A$70,$A11) -> 2 | AA11: Filled in the same day | AB11: 0 | AC11: Réussite de l'examen de statistiques.
A12: 46232 | B12: =INDEX({"Monday","Tuesday","Wednesday","Thursday","Friday","Saturday","Sunday"},WEEKDAY($A12,2)) -> Wednesday | C12: Yes | D12: =COUNTIFS(Intentions!$B$2:$B$365,$A12) -> 7 | E12: =COUNTIFS(Intentions!$B$2:$B$365,$A12,Intentions!$H$2:$H$365,"<>Planned") -> 7 | F12: =COUNTIFS(Intentions!$B$2:$B$365,$A12,Intentions!$H$2:$H$365,"Done")+COUNTIFS(Intentions!$B$2:$B$365,$A12,Intentions!$H$2:$H$365,"Partial") -> 0 | G12: =IF(E12=0,"",SUMIFS(Intentions!$K$2:$K$365,Intentions!$B$2:$B$365,$A12)/E12) -> 0 | H12: =SUMIFS(Intentions!$G$2:$G$365,Intentions!$B$2:$B$365,$A12) -> 245 | I12: =SUMIFS(Activities!$F$2:$F$190,Activities!$B$2:$B$190,$A12) -> 0 | J12: =SUMIFS(Activities!$F$2:$F$190,Activities!$B$2:$B$190,$A12,Activities!$C$2:$C$190,"Spiritual") -> 0 | K12: =SUMIFS(Activities!$F$2:$F$190,Activities!$B$2:$B$190,$A12,Activities!$C$2:$C$190,"Physical") -> 0 | L12: =SUMIFS(Activities!$F$2:$F$190,Activities!$B$2:$B$190,$A12,Activities!$C$2:$C$190,"Studies") -> 0 | M12: =SUMIFS(Activities!$F$2:$F$190,Activities!$B$2:$B$190,$A12,Activities!$C$2:$C$190,"Professional") -> 0 | N12: =SUMIFS(Activities!$F$2:$F$190,Activities!$B$2:$B$190,$A12,Activities!$C$2:$C$190,"Personal") -> 0 | O12: =SUMIFS(Activities!$F$2:$F$190,Activities!$B$2:$B$190,$A12,Activities!$C$2:$C$190,"Relationships") -> 0 | P12: =SUMIFS(Activities!$F$2:$F$190,Activities!$B$2:$B$190,$A12,Activities!$C$2:$C$190,"Leisure and creativity") -> 0 | Q12: 6.1 | S12: 2 | T12: 1 | U12: 2 | V12: 4 | W12: 207 | X12: 10425 | Y12: 2.7 | Z12: =COUNTIFS(Reflections!$A$2:$A$70,$A12) -> 0 | AA12: Filled in the same day | AB12: 0
A13: 46233 | B13: =INDEX({"Monday","Tuesday","Wednesday","Thursday","Friday","Saturday","Sunday"},WEEKDAY($A13,2)) -> Thursday | C13: Yes | D13: =COUNTIFS(Intentions!$B$2:$B$365,$A13) -> 3 | E13: =COUNTIFS(Intentions!$B$2:$B$365,$A13,Intentions!$H$2:$H$365,"<>Planned") -> 3 | F13: =COUNTIFS(Intentions!$B$2:$B$365,$A13,Intentions!$H$2:$H$365,"Done")+COUNTIFS(Intentions!$B$2:$B$365,$A13,Intentions!$H$2:$H$365,"Partial") -> 2 | G13: =IF(E13=0,"",SUMIFS(Intentions!$K$2:$K$365,Intentions!$B$2:$B$365,$A13)/E13) -> 0.5 | H13: =SUMIFS(Intentions!$G$2:$G$365,Intentions!$B$2:$B$365,$A13) -> 165 | I13: =SUMIFS(Activities!$F$2:$F$190,Activities!$B$2:$B$190,$A13) -> 99 | J13: =SUMIFS(Activities!$F$2:$F$190,Activities!$B$2:$B$190,$A13,Activities!$C$2:$C$190,"Spiritual") -> 0 | K13: =SUMIFS(Activities!$F$2:$F$190,Activities!$B$2:$B$190,$A13,Activities!$C$2:$C$190,"Physical") -> 0 | L13: =SUMIFS(Activities!$F$2:$F$190,Activities!$B$2:$B$190,$A13,Activities!$C$2:$C$190,"Studies") -> 99 | M13: =SUMIFS(Activities!$F$2:$F$190,Activities!$B$2:$B$190,$A13,Activities!$C$2:$C$190,"Professional") -> 0 | N13: =SUMIFS(Activities!$F$2:$F$190,Activities!$B$2:$B$190,$A13,Activities!$C$2:$C$190,"Personal") -> 0 | O13: =SUMIFS(Activities!$F$2:$F$190,Activities!$B$2:$B$190,$A13,Activities!$C$2:$C$190,"Relationships") -> 0 | P13: =SUMIFS(Activities!$F$2:$F$190,Activities!$B$2:$B$190,$A13,Activities!$C$2:$C$190,"Leisure and creativity") -> 0 | Q13: 7.7 | S13: 3 | T13: 2 | U13: 3 | V13: 4 | W13: 221 | X13: 7114 | Y13: 2.3 | Z13: =COUNTIFS(Reflections!$A$2:$A$70,$A13) -> 0 | AA13: Caught up later | AB13: 2
A14: 46234 | B14: =INDEX({"Monday","Tuesday","Wednesday","Thursday","Friday","Saturday","Sunday"},WEEKDAY($A14,2)) -> Friday | C14: Yes | D14: =COUNTIFS(Intentions!$B$2:$B$365,$A14) -> 7 | E14: =COUNTIFS(Intentions!$B$2:$B$365,$A14,Intentions!$H$2:$H$365,"<>Planned") -> 0 | F14: =COUNTIFS(Intentions!$B$2:$B$365,$A14,Intentions!$H$2:$H$365,"Done")+COUNTIFS(Intentions!$B$2:$B$365,$A14,Intentions!$H$2:$H$365,"Partial") -> 0 | G14: =IF(E14=0,"",SUMIFS(Intentions!$K$2:$K$365,Intentions!$B$2:$B$365,$A14)/E14) | H14: =SUMIFS(Intentions!$G$2:$G$365,Intentions!$B$2:$B$365,$A14) -> 345 | I14: =SUMIFS(Activities!$F$2:$F$190,Activities!$B$2:$B$190,$A14) -> 0 | J14: =SUMIFS(Activities!$F$2:$F$190,Activities!$B$2:$B$190,$A14,Activities!$C$2:$C$190,"Spiritual") -> 0 | K14: =SUMIFS(Activities!$F$2:$F$190,Activities!$B$2:$B$190,$A14,Activities!$C$2:$C$190,"Physical") -> 0 | L14: =SUMIFS(Activities!$F$2:$F$190,Activities!$B$2:$B$190,$A14,Activities!$C$2:$C$190,"Studies") -> 0 | M14: =SUMIFS(Activities!$F$2:$F$190,Activities!$B$2:$B$190,$A14,Activities!$C$2:$C$190,"Professional") -> 0 | N14: =SUMIFS(Activities!$F$2:$F$190,Activities!$B$2:$B$190,$A14,Activities!$C$2:$C$190,"Personal") -> 0 | O14: =SUMIFS(Activities!$F$2:$F$190,Activities!$B$2:$B$190,$A14,Activities!$C$2:$C$190,"Relationships") -> 0 | P14: =SUMIFS(Activities!$F$2:$F$190,Activities!$B$2:$B$190,$A14,Activities!$C$2:$C$190,"Leisure and creativity") -> 0 | Q14: 7.6 | S14: 3 | T14: 4 | U14: 4 | V14: 2 | W14: 164 | X14: 6806 | Y14: 1.8 | Z14: =COUNTIFS(Reflections!$A$2:$A$70,$A14) -> 0 | AA14: Filled in the same day | AB14: 0
A15: 46235 | B15: =INDEX({"Monday","Tuesday","Wednesday","Thursday","Friday","Saturday","Sunday"},WEEKDAY($A15,2)) -> Saturday | C15: Yes | D15: =COUNTIFS(Intentions!$B$2:$B$365,$A15) -> 6 | E15: =COUNTIFS(Intentions!$B$2:$B$365,$A15,Intentions!$H$2:$H$365,"<>Planned") -> 6 | F15: =COUNTIFS(Intentions!$B$2:$B$365,$A15,Intentions!$H$2:$H$365,"Done")+COUNTIFS(Intentions!$B$2:$B$365,$A15,Intentions!$H$2:$H$365,"Partial") -> 2 | G15: =IF(E15=0,"",SUMIFS(Intentions!$K$2:$K$365,Intentions!$B$2:$B$365,$A15)/E15) -> 0.33333333 | H15: =SUMIFS(Intentions!$G$2:$G$365,Intentions!$B$2:$B$365,$A15) -> 315 | I15: =SUMIFS(Activities!$F$2:$F$190,Activities!$B$2:$B$190,$A15) -> 51 | J15: =SUMIFS(Activities!$F$2:$F$190,Activities!$B$2:$B$190,$A15,Activities!$C$2:$C$190,"Spiritual") -> 17 | K15: =SUMIFS(Activities!$F$2:$F$190,Activities!$B$2:$B$190,$A15,Activities!$C$2:$C$190,"Physical") -> 34 | L15: =SUMIFS(Activities!$F$2:$F$190,Activities!$B$2:$B$190,$A15,Activities!$C$2:$C$190,"Studies") -> 0 | M15: =SUMIFS(Activities!$F$2:$F$190,Activities!$B$2:$B$190,$A15,Activities!$C$2:$C$190,"Professional") -> 0 | N15: =SUMIFS(Activities!$F$2:$F$190,Activities!$B$2:$B$190,$A15,Activities!$C$2:$C$190,"Personal") -> 0 | O15: =SUMIFS(Activities!$F$2:$F$190,Activities!$B$2:$B$190,$A15,Activities!$C$2:$C$190,"Relationships") -> 0 | P15: =SUMIFS(Activities!$F$2:$F$190,Activities!$B$2:$B$190,$A15,Activities!$C$2:$C$190,"Leisure and creativity") -> 0 | Q15: 9.5 | S15: 4 | T15: 2 | U15: 3 | V15: 2 | W15: 135 | X15: 4487 | Y15: 2.2 | Z15: =COUNTIFS(Reflections!$A$2:$A$70,$A15) -> 2 | AA15: Filled in the same day | AB15: 0 | AC15: Culte très édifiant ce dimanche.
A16: 46236 | B16: =INDEX({"Monday","Tuesday","Wednesday","Thursday","Friday","Saturday","Sunday"},WEEKDAY($A16,2)) -> Sunday | C16: No | D16: =COUNTIFS(Intentions!$B$2:$B$365,$A16) -> 0 | E16: =COUNTIFS(Intentions!$B$2:$B$365,$A16,Intentions!$H$2:$H$365,"<>Planned") -> 0 | F16: =COUNTIFS(Intentions!$B$2:$B$365,$A16,Intentions!$H$2:$H$365,"Done")+COUNTIFS(Intentions!$B$2:$B$365,$A16,Intentions!$H$2:$H$365,"Partial") -> 0 | G16: =IF(E16=0,"",SUMIFS(Intentions!$K$2:$K$365,Intentions!$B$2:$B$365,$A16)/E16) | H16: =SUMIFS(Intentions!$G$2:$G$365,Intentions!$B$2:$B$365,$A16) -> 0 | I16: =SUMIFS(Activities!$F$2:$F$190,Activities!$B$2:$B$190,$A16) -> 0 | J16: =SUMIFS(Activities!$F$2:$F$190,Activities!$B$2:$B$190,$A16,Activities!$C$2:$C$190,"Spiritual") -> 0 | K16: =SUMIFS(Activities!$F$2:$F$190,Activities!$B$2:$B$190,$A16,Activities!$C$2:$C$190,"Physical") -> 0 | L16: =SUMIFS(Activities!$F$2:$F$190,Activities!$B$2:$B$190,$A16,Activities!$C$2:$C$190,"Studies") -> 0 | M16: =SUMIFS(Activities!$F$2:$F$190,Activities!$B$2:$B$190,$A16,Activities!$C$2:$C$190,"Professional") -> 0 | N16: =SUMIFS(Activities!$F$2:$F$190,Activities!$B$2:$B$190,$A16,Activities!$C$2:$C$190,"Personal") -> 0 | O16: =SUMIFS(Activities!$F$2:$F$190,Activities!$B$2:$B$190,$A16,Activities!$C$2:$C$190,"Relationships") -> 0 | P16: =SUMIFS(Activities!$F$2:$F$190,Activities!$B$2:$B$190,$A16,Activities!$C$2:$C$190,"Leisure and creativity") -> 0 | Z16: =COUNTIFS(Reflections!$A$2:$A$70,$A16) -> 0 | AA16: Forgotten (locked)
A17: 46237 | B17: =INDEX({"Monday","Tuesday","Wednesday","Thursday","Friday","Saturday","Sunday"},WEEKDAY($A17,2)) -> Monday | C17: Yes | D17: =COUNTIFS(Intentions!$B$2:$B$365,$A17) -> 4 | E17: =COUNTIFS(Intentions!$B$2:$B$365,$A17,Intentions!$H$2:$H$365,"<>Planned") -> 4 | F17: =COUNTIFS(Intentions!$B$2:$B$365,$A17,Intentions!$H$2:$H$365,"Done")+COUNTIFS(Intentions!$B$2:$B$365,$A17,Intentions!$H$2:$H$365,"Partial") -> 2 | G17: =IF(E17=0,"",SUMIFS(Intentions!$K$2:$K$365,Intentions!$B$2:$B$365,$A17)/E17) -> 0.5 | H17: =SUMIFS(Intentions!$G$2:$G$365,Intentions!$B$2:$B$365,$A17) -> 125 | I17: =SUMIFS(Activities!$F$2:$F$190,Activities!$B$2:$B$190,$A17) -> 49 | J17: =SUMIFS(Activities!$F$2:$F$190,Activities!$B$2:$B$190,$A17,Activities!$C$2:$C$190,"Spiritual") -> 24 | K17: =SUMIFS(Activities!$F$2:$F$190,Activities!$B$2:$B$190,$A17,Activities!$C$2:$C$190,"Physical") -> 0 | L17: =SUMIFS(Activities!$F$2:$F$190,Activities!$B$2:$B$190,$A17,Activities!$C$2:$C$190,"Studies") -> 0 | M17: =SUMIFS(Activities!$F$2:$F$190,Activities!$B$2:$B$190,$A17,Activities!$C$2:$C$190,"Professional") -> 0 | N17: =SUMIFS(Activities!$F$2:$F$190,Activities!$B$2:$B$190,$A17,Activities!$C$2:$C$190,"Personal") -> 0 | O17: =SUMIFS(Activities!$F$2:$F$190,Activities!$B$2:$B$190,$A17,Activities!$C$2:$C$190,"Relationships") -> 25 | P17: =SUMIFS(Activities!$F$2:$F$190,Activities!$B$2:$B$190,$A17,Activities!$C$2:$C$190,"Leisure and creativity") -> 0 | Q17: 5.9 | S17: 1 | T17: 1 | U17: 3 | V17: 4 | W17: 291 | X17: 8259 | Y17: 1.7 | Z17: =COUNTIFS(Reflections!$A$2:$A$70,$A17) -> 0 | AA17: Filled in the same day | AB17: 0
A18: 46238 | B18: =INDEX({"Monday","Tuesday","Wednesday","Thursday","Friday","Saturday","Sunday"},WEEKDAY($A18,2)) -> Tuesday | C18: Yes | D18: =COUNTIFS(Intentions!$B$2:$B$365,$A18) -> 5 | E18: =COUNTIFS(Intentions!$B$2:$B$365,$A18,Intentions!$H$2:$H$365,"<>Planned") -> 5 | F18: =COUNTIFS(Intentions!$B$2:$B$365,$A18,Intentions!$H$2:$H$365,"Done")+COUNTIFS(Intentions!$B$2:$B$365,$A18,Intentions!$H$2:$H$365,"Partial") -> 2 | G18: =IF(E18=0,"",SUMIFS(Intentions!$K$2:$K$365,Intentions!$B$2:$B$365,$A18)/E18) -> 0.4 | H18: =SUMIFS(Intentions!$G$2:$G$365,Intentions!$B$2:$B$365,$A18) -> 300 | I18: =SUMIFS(Activities!$F$2:$F$190,Activities!$B$2:$B$190,$A18) -> 270 | J18: =SUMIFS(Activities!$F$2:$F$190,Activities!$B$2:$B$190,$A18,Activities!$C$2:$C$190,"Spiritual") -> 0 | K18: =SUMIFS(Activities!$F$2:$F$190,Activities!$B$2:$B$190,$A18,Activities!$C$2:$C$190,"Physical") -> 0 | L18: =SUMIFS(Activities!$F$2:$F$190,Activities!$B$2:$B$190,$A18,Activities!$C$2:$C$190,"Studies") -> 270 | M18: =SUMIFS(Activities!$F$2:$F$190,Activities!$B$2:$B$190,$A18,Activities!$C$2:$C$190,"Professional") -> 0 | N18: =SUMIFS(Activities!$F$2:$F$190,Activities!$B$2:$B$190,$A18,Activities!$C$2:$C$190,"Personal") -> 0 | O18: =SUMIFS(Activities!$F$2:$F$190,Activities!$B$2:$B$190,$A18,Activities!$C$2:$C$190,"Relationships") -> 0 | P18: =SUMIFS(Activities!$F$2:$F$190,Activities!$B$2:$B$190,$A18,Activities!$C$2:$C$190,"Leisure and creativity") -> 0 | Q18: 5.4 | S18: 2 | T18: 1 | U18: 4 | V18: 2 | W18: 173 | X18: 8999 | Y18: 1.6 | Z18: =COUNTIFS(Reflections!$A$2:$A$70,$A18) -> 1 | AA18: Filled in the same day | AB18: 0
A19: 46239 | B19: =INDEX({"Monday","Tuesday","Wednesday","Thursday","Friday","Saturday","Sunday"},WEEKDAY($A19,2)) -> Wednesday | C19: Yes | D19: =COUNTIFS(Intentions!$B$2:$B$365,$A19) -> 4 | E19: =COUNTIFS(Intentions!$B$2:$B$365,$A19,Intentions!$H$2:$H$365,"<>Planned") -> 4 | F19: =COUNTIFS(Intentions!$B$2:$B$365,$A19,Intentions!$H$2:$H$365,"Done")+COUNTIFS(Intentions!$B$2:$B$365,$A19,Intentions!$H$2:$H$365,"Partial") -> 3 | G19: =IF(E19=0,"",SUMIFS(Intentions!$K$2:$K$365,Intentions!$B$2:$B$365,$A19)/E19) -> 0.75 | H19: =SUMIFS(Intentions!$G$2:$G$365,Intentions!$B$2:$B$365,$A19) -> 250 | I19: =SUMIFS(Activities!$F$2:$F$190,Activities!$B$2:$B$190,$A19) -> 337 | J19: =SUMIFS(Activities!$F$2:$F$190,Activities!$B$2:$B$190,$A19,Activities!$C$2:$C$190,"Spiritual") -> 0 | K19: =SUMIFS(Activities!$F$2:$F$190,Activities!$B$2:$B$190,$A19,Activities!$C$2:$C$190,"Physical") -> 29 | L19: =SUMIFS(Activities!$F$2:$F$190,Activities!$B$2:$B$190,$A19,Activities!$C$2:$C$190,"Studies") -> 248 | M19: =SUMIFS(Activities!$F$2:$F$190,Activities!$B$2:$B$190,$A19,Activities!$C$2:$C$190,"Professional") -> 0 | N19: =SUMIFS(Activities!$F$2:$F$190,Activities!$B$2:$B$190,$A19,Activities!$C$2:$C$190,"Personal") -> 0 | O19: =SUMIFS(Activities!$F$2:$F$190,Activities!$B$2:$B$190,$A19,Activities!$C$2:$C$190,"Relationships") -> 0 | P19: =SUMIFS(Activities!$F$2:$F$190,Activities!$B$2:$B$190,$A19,Activities!$C$2:$C$190,"Leisure and creativity") -> 60 | Q19: 7.6 | S19: 5 | T19: 5 | U19: 4 | V19: 4 | W19: 215 | X19: 3137 | Y19: 2.6 | Z19: =COUNTIFS(Reflections!$A$2:$A$70,$A19) -> 1 | AA19: Filled in the same day | AB19: 0
A20: 46240 | B20: =INDEX({"Monday","Tuesday","Wednesday","Thursday","Friday","Saturday","Sunday"},WEEKDAY($A20,2)) -> Thursday | C20: Yes | D20: =COUNTIFS(Intentions!$B$2:$B$365,$A20) -> 4 | E20: =COUNTIFS(Intentions!$B$2:$B$365,$A20,Intentions!$H$2:$H$365,"<>Planned") -> 4 | F20: =COUNTIFS(Intentions!$B$2:$B$365,$A20,Intentions!$H$2:$H$365,"Done")+COUNTIFS(Intentions!$B$2:$B$365,$A20,Intentions!$H$2:$H$365,"Partial") -> 4 | G20: =IF(E20=0,"",SUMIFS(Intentions!$K$2:$K$365,Intentions!$B$2:$B$365,$A20)/E20) -> 1 | H20: =SUMIFS(Intentions!$G$2:$G$365,Intentions!$B$2:$B$365,$A20) -> 240 | I20: =SUMIFS(Activities!$F$2:$F$190,Activities!$B$2:$B$190,$A20) -> 326 | J20: =SUMIFS(Activities!$F$2:$F$190,Activities!$B$2:$B$190,$A20,Activities!$C$2:$C$190,"Spiritual") -> 0 | K20: =SUMIFS(Activities!$F$2:$F$190,Activities!$B$2:$B$190,$A20,Activities!$C$2:$C$190,"Physical") -> 26 | L20: =SUMIFS(Activities!$F$2:$F$190,Activities!$B$2:$B$190,$A20,Activities!$C$2:$C$190,"Studies") -> 221 | M20: =SUMIFS(Activities!$F$2:$F$190,Activities!$B$2:$B$190,$A20,Activities!$C$2:$C$190,"Professional") -> 0 | N20: =SUMIFS(Activities!$F$2:$F$190,Activities!$B$2:$B$190,$A20,Activities!$C$2:$C$190,"Personal") -> 0 | O20: =SUMIFS(Activities!$F$2:$F$190,Activities!$B$2:$B$190,$A20,Activities!$C$2:$C$190,"Relationships") -> 19 | P20: =SUMIFS(Activities!$F$2:$F$190,Activities!$B$2:$B$190,$A20,Activities!$C$2:$C$190,"Leisure and creativity") -> 60 | Q20: 6 | S20: 3 | T20: 5 | U20: 4 | V20: 1 | W20: 181 | X20: 9773 | Y20: 1.3 | Z20: =COUNTIFS(Reflections!$A$2:$A$70,$A20) -> 0 | AA20: Filled in the same day | AB20: 0
A21: 46241 | B21: =INDEX({"Monday","Tuesday","Wednesday","Thursday","Friday","Saturday","Sunday"},WEEKDAY($A21,2)) -> Friday | C21: Yes | D21: =COUNTIFS(Intentions!$B$2:$B$365,$A21) -> 5 | E21: =COUNTIFS(Intentions!$B$2:$B$365,$A21,Intentions!$H$2:$H$365,"<>Planned") -> 5 | F21: =COUNTIFS(Intentions!$B$2:$B$365,$A21,Intentions!$H$2:$H$365,"Done")+COUNTIFS(Intentions!$B$2:$B$365,$A21,Intentions!$H$2:$H$365,"Partial") -> 2 | G21: =IF(E21=0,"",SUMIFS(Intentions!$K$2:$K$365,Intentions!$B$2:$B$365,$A21)/E21) -> 0.4 | H21: =SUMIFS(Intentions!$G$2:$G$365,Intentions!$B$2:$B$365,$A21) -> 255 | I21: =SUMIFS(Activities!$F$2:$F$190,Activities!$B$2:$B$190,$A21) -> 46 | J21: =SUMIFS(Activities!$F$2:$F$190,Activities!$B$2:$B$190,$A21,Activities!$C$2:$C$190,"Spiritual") -> 16 | K21: =SUMIFS(Activities!$F$2:$F$190,Activities!$B$2:$B$190,$A21,Activities!$C$2:$C$190,"Physical") -> 30 | L21: =SUMIFS(Activities!$F$2:$F$190,Activities!$B$2:$B$190,$A21,Activities!$C$2:$C$190,"Studies") -> 0 | M21: =SUMIFS(Activities!$F$2:$F$190,Activities!$B$2:$B$190,$A21,Activities!$C$2:$C$190,"Professional") -> 0 | N21: =SUMIFS(Activities!$F$2:$F$190,Activities!$B$2:$B$190,$A21,Activities!$C$2:$C$190,"Personal") -> 0 | O21: =SUMIFS(Activities!$F$2:$F$190,Activities!$B$2:$B$190,$A21,Activities!$C$2:$C$190,"Relationships") -> 0 | P21: =SUMIFS(Activities!$F$2:$F$190,Activities!$B$2:$B$190,$A21,Activities!$C$2:$C$190,"Leisure and creativity") -> 0 | Q21: 6.2 | S21: 3 | T21: 2 | U21: 2 | V21: 3 | W21: 147 | X21: 5833 | Y21: 1.1 | Z21: =COUNTIFS(Reflections!$A$2:$A$70,$A21) -> 1 | AA21: Filled in the same day | AB21: 0
A22: 46242 | B22: =INDEX({"Monday","Tuesday","Wednesday","Thursday","Friday","Saturday","Sunday"},WEEKDAY($A22,2)) -> Saturday | C22: Yes | D22: =COUNTIFS(Intentions!$B$2:$B$365,$A22) -> 2 | E22: =COUNTIFS(Intentions!$B$2:$B$365,$A22,Intentions!$H$2:$H$365,"<>Planned") -> 2 | F22: =COUNTIFS(Intentions!$B$2:$B$365,$A22,Intentions!$H$2:$H$365,"Done")+COUNTIFS(Intentions!$B$2:$B$365,$A22,Intentions!$H$2:$H$365,"Partial") -> 2 | G22: =IF(E22=0,"",SUMIFS(Intentions!$K$2:$K$365,Intentions!$B$2:$B$365,$A22)/E22) -> 1 | H22: =SUMIFS(Intentions!$G$2:$G$365,Intentions!$B$2:$B$365,$A22) -> 100 | I22: =SUMIFS(Activities!$F$2:$F$190,Activities!$B$2:$B$190,$A22) -> 181 | J22: =SUMIFS(Activities!$F$2:$F$190,Activities!$B$2:$B$190,$A22,Activities!$C$2:$C$190,"Spiritual") -> 0 | K22: =SUMIFS(Activities!$F$2:$F$190,Activities!$B$2:$B$190,$A22,Activities!$C$2:$C$190,"Physical") -> 40 | L22: =SUMIFS(Activities!$F$2:$F$190,Activities!$B$2:$B$190,$A22,Activities!$C$2:$C$190,"Studies") -> 81 | M22: =SUMIFS(Activities!$F$2:$F$190,Activities!$B$2:$B$190,$A22,Activities!$C$2:$C$190,"Professional") -> 0 | N22: =SUMIFS(Activities!$F$2:$F$190,Activities!$B$2:$B$190,$A22,Activities!$C$2:$C$190,"Personal") -> 0 | O22: =SUMIFS(Activities!$F$2:$F$190,Activities!$B$2:$B$190,$A22,Activities!$C$2:$C$190,"Relationships") -> 0 | P22: =SUMIFS(Activities!$F$2:$F$190,Activities!$B$2:$B$190,$A22,Activities!$C$2:$C$190,"Leisure and creativity") -> 60 | Q22: 7 | S22: 3 | T22: 3 | U22: 4 | V22: 1 | W22: 211 | X22: 6393 | Y22: 2.1 | Z22: =COUNTIFS(Reflections!$A$2:$A$70,$A22) -> 2 | AA22: Filled in the same day | AB22: 0 | AC22: Match de football avec les amis du quartier.
A23: 46243 | B23: =INDEX({"Monday","Tuesday","Wednesday","Thursday","Friday","Saturday","Sunday"},WEEKDAY($A23,2)) -> Sunday | C23: Yes | D23: =COUNTIFS(Intentions!$B$2:$B$365,$A23) -> 7 | E23: =COUNTIFS(Intentions!$B$2:$B$365,$A23,Intentions!$H$2:$H$365,"<>Planned") -> 7 | F23: =COUNTIFS(Intentions!$B$2:$B$365,$A23,Intentions!$H$2:$H$365,"Done")+COUNTIFS(Intentions!$B$2:$B$365,$A23,Intentions!$H$2:$H$365,"Partial") -> 1 | G23: =IF(E23=0,"",SUMIFS(Intentions!$K$2:$K$365,Intentions!$B$2:$B$365,$A23)/E23) -> 0.14285714 | H23: =SUMIFS(Intentions!$G$2:$G$365,Intentions!$B$2:$B$365,$A23) -> 310 | I23: =SUMIFS(Activities!$F$2:$F$190,Activities!$B$2:$B$190,$A23) -> 35 | J23: =SUMIFS(Activities!$F$2:$F$190,Activities!$B$2:$B$190,$A23,Activities!$C$2:$C$190,"Spiritual") -> 0 | K23: =SUMIFS(Activities!$F$2:$F$190,Activities!$B$2:$B$190,$A23,Activities!$C$2:$C$190,"Physical") -> 0 | L23: =SUMIFS(Activities!$F$2:$F$190,Activities!$B$2:$B$190,$A23,Activities!$C$2:$C$190,"Studies") -> 0 | M23: =SUMIFS(Activities!$F$2:$F$190,Activities!$B$2:$B$190,$A23,Activities!$C$2:$C$190,"Professional") -> 0 | N23: =SUMIFS(Activities!$F$2:$F$190,Activities!$B$2:$B$190,$A23,Activities!$C$2:$C$190,"Personal") -> 35 | O23: =SUMIFS(Activities!$F$2:$F$190,Activities!$B$2:$B$190,$A23,Activities!$C$2:$C$190,"Relationships") -> 0 | P23: =SUMIFS(Activities!$F$2:$F$190,Activities!$B$2:$B$190,$A23,Activities!$C$2:$C$190,"Leisure and creativity") -> 0 | Q23: 7.6 | S23: 3 | T23: 3 | U23: 2 | V23: 2 | W23: 193 | X23: 11192 | Y23: 2.1 | Z23: =COUNTIFS(Reflections!$A$2:$A$70,$A23) -> 3 | AA23: Filled in the same day | AB23: 0
A24: 46244 | B24: =INDEX({"Monday","Tuesday","Wednesday","Thursday","Friday","Saturday","Sunday"},WEEKDAY($A24,2)) -> Monday | C24: Yes | D24: =COUNTIFS(Intentions!$B$2:$B$365,$A24) -> 5 | E24: =COUNTIFS(Intentions!$B$2:$B$365,$A24,Intentions!$H$2:$H$365,"<>Planned") -> 5 | F24: =COUNTIFS(Intentions!$B$2:$B$365,$A24,Intentions!$H$2:$H$365,"Done")+COUNTIFS(Intentions!$B$2:$B$365,$A24,Intentions!$H$2:$H$365,"Partial") -> 4 | G24: =IF(E24=0,"",SUMIFS(Intentions!$K$2:$K$365,Intentions!$B$2:$B$365,$A24)/E24) -> 0.8 | H24: =SUMIFS(Intentions!$G$2:$G$365,Intentions!$B$2:$B$365,$A24) -> 185 | I24: =SUMIFS(Activities!$F$2:$F$190,Activities!$B$2:$B$190,$A24) -> 159 | J24: =SUMIFS(Activities!$F$2:$F$190,Activities!$B$2:$B$190,$A24,Activities!$C$2:$C$190,"Spiritual") -> 18 | K24: =SUMIFS(Activities!$F$2:$F$190,Activities!$B$2:$B$190,$A24,Activities!$C$2:$C$190,"Physical") -> 0 | L24: =SUMIFS(Activities!$F$2:$F$190,Activities!$B$2:$B$190,$A24,Activities!$C$2:$C$190,"Studies") -> 110 | M24: =SUMIFS(Activities!$F$2:$F$190,Activities!$B$2:$B$190,$A24,Activities!$C$2:$C$190,"Professional") -> 0 | N24: =SUMIFS(Activities!$F$2:$F$190,Activities!$B$2:$B$190,$A24,Activities!$C$2:$C$190,"Personal") -> 0 | O24: =SUMIFS(Activities!$F$2:$F$190,Activities!$B$2:$B$190,$A24,Activities!$C$2:$C$190,"Relationships") -> 31 | P24: =SUMIFS(Activities!$F$2:$F$190,Activities!$B$2:$B$190,$A24,Activities!$C$2:$C$190,"Leisure and creativity") -> 0 | Q24: 7.6 | S24: 4 | T24: 5 | U24: 5 | V24: 1 | W24: 303 | X24: 8475 | Y24: 1.7 | Z24: =COUNTIFS(Reflections!$A$2:$A$70,$A24) -> 1 | AA24: Filled in the same day | AB24: 0
A25: 46245 | B25: =INDEX({"Monday","Tuesday","Wednesday","Thursday","Friday","Saturday","Sunday"},WEEKDAY($A25,2)) -> Tuesday | C25: Yes | D25: =COUNTIFS(Intentions!$B$2:$B$365,$A25) -> 7 | E25: =COUNTIFS(Intentions!$B$2:$B$365,$A25,Intentions!$H$2:$H$365,"<>Planned") -> 7 | F25: =COUNTIFS(Intentions!$B$2:$B$365,$A25,Intentions!$H$2:$H$365,"Done")+COUNTIFS(Intentions!$B$2:$B$365,$A25,Intentions!$H$2:$H$365,"Partial") -> 2 | G25: =IF(E25=0,"",SUMIFS(Intentions!$K$2:$K$365,Intentions!$B$2:$B$365,$A25)/E25) -> 0.21428571 | H25: =SUMIFS(Intentions!$G$2:$G$365,Intentions!$B$2:$B$365,$A25) -> 390 | I25: =SUMIFS(Activities!$F$2:$F$190,Activities!$B$2:$B$190,$A25) -> 121 | J25: =SUMIFS(Activities!$F$2:$F$190,Activities!$B$2:$B$190,$A25,Activities!$C$2:$C$190,"Spiritual") -> 0 | K25: =SUMIFS(Activities!$F$2:$F$190,Activities!$B$2:$B$190,$A25,Activities!$C$2:$C$190,"Physical") -> 0 | L25: =SUMIFS(Activities!$F$2:$F$190,Activities!$B$2:$B$190,$A25,Activities!$C$2:$C$190,"Studies") -> 54 | M25: =SUMIFS(Activities!$F$2:$F$190,Activities!$B$2:$B$190,$A25,Activities!$C$2:$C$190,"Professional") -> 67 | N25: =SUMIFS(Activities!$F$2:$F$190,Activities!$B$2:$B$190,$A25,Activities!$C$2:$C$190,"Personal") -> 0 | O25: =SUMIFS(Activities!$F$2:$F$190,Activities!$B$2:$B$190,$A25,Activities!$C$2:$C$190,"Relationships") -> 0 | P25: =SUMIFS(Activities!$F$2:$F$190,Activities!$B$2:$B$190,$A25,Activities!$C$2:$C$190,"Leisure and creativity") -> 0 | Q25: 7.5 | S25: 3 | T25: 2 | U25: 2 | V25: 3 | W25: 209 | X25: 6843 | Y25: 2.1 | Z25: =COUNTIFS(Reflections!$A$2:$A$70,$A25) -> 1 | AA25: Filled in the same day | AB25: 0
A26: 46246 | B26: =INDEX({"Monday","Tuesday","Wednesday","Thursday","Friday","Saturday","Sunday"},WEEKDAY($A26,2)) -> Wednesday | C26: Yes | D26: =COUNTIFS(Intentions!$B$2:$B$365,$A26) -> 7 | E26: =COUNTIFS(Intentions!$B$2:$B$365,$A26,Intentions!$H$2:$H$365,"<>Planned") -> 7 | F26: =COUNTIFS(Intentions!$B$2:$B$365,$A26,Intentions!$H$2:$H$365,"Done")+COUNTIFS(Intentions!$B$2:$B$365,$A26,Intentions!$H$2:$H$365,"Partial") -> 1 | G26: =IF(E26=0,"",SUMIFS(Intentions!$K$2:$K$365,Intentions!$B$2:$B$365,$A26)/E26) -> 0.14285714 | H26: =SUMIFS(Intentions!$G$2:$G$365,Intentions!$B$2:$B$365,$A26) -> 390 | I26: =SUMIFS(Activities!$F$2:$F$190,Activities!$B$2:$B$190,$A26) -> 90 | J26: =SUMIFS(Activities!$F$2:$F$190,Activities!$B$2:$B$190,$A26,Activities!$C$2:$C$190,"Spiritual") -> 0 | K26: =SUMIFS(Activities!$F$2:$F$190,Activities!$B$2:$B$190,$A26,Activities!$C$2:$C$190,"Physical") -> 30 | L26: =SUMIFS(Activities!$F$2:$F$190,Activities!$B$2:$B$190,$A26,Activities!$C$2:$C$190,"Studies") -> 0 | M26: =SUMIFS(Activities!$F$2:$F$190,Activities!$B$2:$B$190,$A26,Activities!$C$2:$C$190,"Professional") -> 0 | N26: =SUMIFS(Activities!$F$2:$F$190,Activities!$B$2:$B$190,$A26,Activities!$C$2:$C$190,"Personal") -> 0 | O26: =SUMIFS(Activities!$F$2:$F$190,Activities!$B$2:$B$190,$A26,Activities!$C$2:$C$190,"Relationships") -> 0 | P26: =SUMIFS(Activities!$F$2:$F$190,Activities!$B$2:$B$190,$A26,Activities!$C$2:$C$190,"Leisure and creativity") -> 60 | Q26: 5.8 | S26: 3 | T26: 3 | U26: 3 | V26: 2 | W26: 182 | X26: 10482 | Y26: 1.9 | Z26: =COUNTIFS(Reflections!$A$2:$A$70,$A26) -> 0 | AA26: Filled in the same day | AB26: 0
A27: 46247 | B27: =INDEX({"Monday","Tuesday","Wednesday","Thursday","Friday","Saturday","Sunday"},WEEKDAY($A27,2)) -> Thursday | C27: Yes | D27: =COUNTIFS(Intentions!$B$2:$B$365,$A27) -> 7 | E27: =COUNTIFS(Intentions!$B$2:$B$365,$A27,Intentions!$H$2:$H$365,"<>Planned") -> 7 | F27: =COUNTIFS(Intentions!$B$2:$B$365,$A27,Intentions!$H$2:$H$365,"Done")+COUNTIFS(Intentions!$B$2:$B$365,$A27,Intentions!$H$2:$H$365,"Partial") -> 4 | G27: =IF(E27=0,"",SUMIFS(Intentions!$K$2:$K$365,Intentions!$B$2:$B$365,$A27)/E27) -> 0.57142857 | H27: =SUMIFS(Intentions!$G$2:$G$365,Intentions!$B$2:$B$365,$A27) -> 300 | I27: =SUMIFS(Activities!$F$2:$F$190,Activities!$B$2:$B$190,$A27) -> 322 | J27: =SUMIFS(Activities!$F$2:$F$190,Activities!$B$2:$B$190,$A27,Activities!$C$2:$C$190,"Spiritual") -> 0 | K27: =SUMIFS(Activities!$F$2:$F$190,Activities!$B$2:$B$190,$A27,Activities!$C$2:$C$190,"Physical") -> 25 | L27: =SUMIFS(Activities!$F$2:$F$190,Activities!$B$2:$B$190,$A27,Activities!$C$2:$C$190,"Studies") -> 58 | M27: =SUMIFS(Activities!$F$2:$F$190,Activities!$B$2:$B$190,$A27,Activities!$C$2:$C$190,"Professional") -> 89 | N27: =SUMIFS(Activities!$F$2:$F$190,Activities!$B$2:$B$190,$A27,Activities!$C$2:$C$190,"Personal") -> 30 | O27: =SUMIFS(Activities!$F$2:$F$190,Activities!$B$2:$B$190,$A27,Activities!$C$2:$C$190,"Relationships") -> 0 | P27: =SUMIFS(Activities!$F$2:$F$190,Activities!$B$2:$B$190,$A27,Activities!$C$2:$C$190,"Leisure and creativity") -> 120 | Q27: 7.3 | S27: 3 | T27: 3 | U27: 4 | V27: 3 | W27: 217 | X27: 9590 | Y27: 1.5 | Z27: =COUNTIFS(Reflections!$A$2:$A$70,$A27) -> 0 | AA27: Filled in the same day | AB27: 0
A28: 46248 | B28: =INDEX({"Monday","Tuesday","Wednesday","Thursday","Friday","Saturday","Sunday"},WEEKDAY($A28,2)) -> Friday | C28: Yes | D28: =COUNTIFS(Intentions!$B$2:$B$365,$A28) -> 3 | E28: =COUNTIFS(Intentions!$B$2:$B$365,$A28,Intentions!$H$2:$H$365,"<>Planned") -> 3 | F28: =COUNTIFS(Intentions!$B$2:$B$365,$A28,Intentions!$H$2:$H$365,"Done")+COUNTIFS(Intentions!$B$2:$B$365,$A28,Intentions!$H$2:$H$365,"Partial") -> 1 | G28: =IF(E28=0,"",SUMIFS(Intentions!$K$2:$K$365,Intentions!$B$2:$B$365,$A28)/E28) -> 0.33333333 | H28: =SUMIFS(Intentions!$G$2:$G$365,Intentions!$B$2:$B$365,$A28) -> 145 | I28: =SUMIFS(Activities!$F$2:$F$190,Activities!$B$2:$B$190,$A28) -> 66 | J28: =SUMIFS(Activities!$F$2:$F$190,Activities!$B$2:$B$190,$A28,Activities!$C$2:$C$190,"Spiritual") -> 0 | K28: =SUMIFS(Activities!$F$2:$F$190,Activities!$B$2:$B$190,$A28,Activities!$C$2:$C$190,"Physical") -> 0 | L28: =SUMIFS(Activities!$F$2:$F$190,Activities!$B$2:$B$190,$A28,Activities!$C$2:$C$190,"Studies") -> 0 | M28: =SUMIFS(Activities!$F$2:$F$190,Activities!$B$2:$B$190,$A28,Activities!$C$2:$C$190,"Professional") -> 66 | N28: =SUMIFS(Activities!$F$2:$F$190,Activities!$B$2:$B$190,$A28,Activities!$C$2:$C$190,"Personal") -> 0 | O28: =SUMIFS(Activities!$F$2:$F$190,Activities!$B$2:$B$190,$A28,Activities!$C$2:$C$190,"Relationships") -> 0 | P28: =SUMIFS(Activities!$F$2:$F$190,Activities!$B$2:$B$190,$A28,Activities!$C$2:$C$190,"Leisure and creativity") -> 0 | Q28: 7.8 | S28: 4 | T28: 5 | U28: 3 | V28: 4 | W28: 226 | X28: 7093 | Y28: 1.4 | Z28: =COUNTIFS(Reflections!$A$2:$A$70,$A28) -> 1 | AA28: Filled in the same day | AB28: 0
A29: 46249 | B29: =INDEX({"Monday","Tuesday","Wednesday","Thursday","Friday","Saturday","Sunday"},WEEKDAY($A29,2)) -> Saturday | C29: Yes | D29: =COUNTIFS(Intentions!$B$2:$B$365,$A29) -> 7 | E29: =COUNTIFS(Intentions!$B$2:$B$365,$A29,Intentions!$H$2:$H$365,"<>Planned") -> 7 | F29: =COUNTIFS(Intentions!$B$2:$B$365,$A29,Intentions!$H$2:$H$365,"Done")+COUNTIFS(Intentions!$B$2:$B$365,$A29,Intentions!$H$2:$H$365,"Partial") -> 3 | G29: =IF(E29=0,"",SUMIFS(Intentions!$K$2:$K$365,Intentions!$B$2:$B$365,$A29)/E29) -> 0.35714286 | H29: =SUMIFS(Intentions!$G$2:$G$365,Intentions!$B$2:$B$365,$A29) -> 255 | I29: =SUMIFS(Activities!$F$2:$F$190,Activities!$B$2:$B$190,$A29) -> 128 | J29: =SUMIFS(Activities!$F$2:$F$190,Activities!$B$2:$B$190,$A29,Activities!$C$2:$C$190,"Spiritual") -> 0 | K29: =SUMIFS(Activities!$F$2:$F$190,Activities!$B$2:$B$190,$A29,Activities!$C$2:$C$190,"Physical") -> 24 | L29: =SUMIFS(Activities!$F$2:$F$190,Activities!$B$2:$B$190,$A29,Activities!$C$2:$C$190,"Studies") -> 80 | M29: =SUMIFS(Activities!$F$2:$F$190,Activities!$B$2:$B$190,$A29,Activities!$C$2:$C$190,"Professional") -> 0 | N29: =SUMIFS(Activities!$F$2:$F$190,Activities!$B$2:$B$190,$A29,Activities!$C$2:$C$190,"Personal") -> 0 | O29: =SUMIFS(Activities!$F$2:$F$190,Activities!$B$2:$B$190,$A29,Activities!$C$2:$C$190,"Relationships") -> 24 | P29: =SUMIFS(Activities!$F$2:$F$190,Activities!$B$2:$B$190,$A29,Activities!$C$2:$C$190,"Leisure and creativity") -> 0 | Q29: 5.5 | S29: 4 | T29: 3 | U29: 2 | V29: 3 | W29: 188 | X29: 5797 | Y29: 1.6 | Z29: =COUNTIFS(Reflections!$A$2:$A$70,$A29) -> 1 | AA29: Filled in the same day | AB29: 0
A30: 46250 | B30: =INDEX({"Monday","Tuesday","Wednesday","Thursday","Friday","Saturday","Sunday"},WEEKDAY($A30,2)) -> Sunday | C30: Yes | D30: =COUNTIFS(Intentions!$B$2:$B$365,$A30) -> 4 | E30: =COUNTIFS(Intentions!$B$2:$B$365,$A30,Intentions!$H$2:$H$365,"<>Planned") -> 4 | F30: =COUNTIFS(Intentions!$B$2:$B$365,$A30,Intentions!$H$2:$H$365,"Done")+COUNTIFS(Intentions!$B$2:$B$365,$A30,Intentions!$H$2:$H$365,"Partial") -> 4 | G30: =IF(E30=0,"",SUMIFS(Intentions!$K$2:$K$365,Intentions!$B$2:$B$365,$A30)/E30) -> 1 | H30: =SUMIFS(Intentions!$G$2:$G$365,Intentions!$B$2:$B$365,$A30) -> 140 | I30: =SUMIFS(Activities!$F$2:$F$190,Activities!$B$2:$B$190,$A30) -> 148 | J30: =SUMIFS(Activities!$F$2:$F$190,Activities!$B$2:$B$190,$A30,Activities!$C$2:$C$190,"Spiritual") -> 19 | K30: =SUMIFS(Activities!$F$2:$F$190,Activities!$B$2:$B$190,$A30,Activities!$C$2:$C$190,"Physical") -> 33 | L30: =SUMIFS(Activities!$F$2:$F$190,Activities!$B$2:$B$190,$A30,Activities!$C$2:$C$190,"Studies") -> 72 | M30: =SUMIFS(Activities!$F$2:$F$190,Activities!$B$2:$B$190,$A30,Activities!$C$2:$C$190,"Professional") -> 0 | N30: =SUMIFS(Activities!$F$2:$F$190,Activities!$B$2:$B$190,$A30,Activities!$C$2:$C$190,"Personal") -> 24 | O30: =SUMIFS(Activities!$F$2:$F$190,Activities!$B$2:$B$190,$A30,Activities!$C$2:$C$190,"Relationships") -> 0 | P30: =SUMIFS(Activities!$F$2:$F$190,Activities!$B$2:$B$190,$A30,Activities!$C$2:$C$190,"Leisure and creativity") -> 0 | Q30: 7.6 | S30: 3 | T30: 3 | U30: 5 | V30: 3 | W30: 311 | X30: 4473 | Y30: 1.8 | Z30: =COUNTIFS(Reflections!$A$2:$A$70,$A30) -> 1 | AA30: Filled in the same day | AB30: 0
A31: 46251 | B31: =INDEX({"Monday","Tuesday","Wednesday","Thursday","Friday","Saturday","Sunday"},WEEKDAY($A31,2)) -> Monday | C31: Yes | D31: =COUNTIFS(Intentions!$B$2:$B$365,$A31) -> 5 | E31: =COUNTIFS(Intentions!$B$2:$B$365,$A31,Intentions!$H$2:$H$365,"<>Planned") -> 5 | F31: =COUNTIFS(Intentions!$B$2:$B$365,$A31,Intentions!$H$2:$H$365,"Done")+COUNTIFS(Intentions!$B$2:$B$365,$A31,Intentions!$H$2:$H$365,"Partial") -> 2 | G31: =IF(E31=0,"",SUMIFS(Intentions!$K$2:$K$365,Intentions!$B$2:$B$365,$A31)/E31) -> 0.4 | H31: =SUMIFS(Intentions!$G$2:$G$365,Intentions!$B$2:$B$365,$A31) -> 210 | I31: =SUMIFS(Activities!$F$2:$F$190,Activities!$B$2:$B$190,$A31) -> 65 | J31: =SUMIFS(Activities!$F$2:$F$190,Activities!$B$2:$B$190,$A31,Activities!$C$2:$C$190,"Spiritual") -> 0 | K31: =SUMIFS(Activities!$F$2:$F$190,Activities!$B$2:$B$190,$A31,Activities!$C$2:$C$190,"Physical") -> 40 | L31: =SUMIFS(Activities!$F$2:$F$190,Activities!$B$2:$B$190,$A31,Activities!$C$2:$C$190,"Studies") -> 0 | M31: =SUMIFS(Activities!$F$2:$F$190,Activities!$B$2:$B$190,$A31,Activities!$C$2:$C$190,"Professional") -> 0 | N31: =SUMIFS(Activities!$F$2:$F$190,Activities!$B$2:$B$190,$A31,Activities!$C$2:$C$190,"Personal") -> 25 | O31: =SUMIFS(Activities!$F$2:$F$190,Activities!$B$2:$B$190,$A31,Activities!$C$2:$C$190,"Relationships") -> 0 | P31: =SUMIFS(Activities!$F$2:$F$190,Activities!$B$2:$B$190,$A31,Activities!$C$2:$C$190,"Leisure and creativity") -> 0 | Q31: 6.9 | S31: 3 | T31: 3 | U31: 3 | V31: 3 | W31: 239 | X31: 7958 | Y31: 1.8 | Z31: =COUNTIFS(Reflections!$A$2:$A$70,$A31) -> 1 | AA31: Filled in the same day | AB31: 0
A32: 46252 | B32: =INDEX({"Monday","Tuesday","Wednesday","Thursday","Friday","Saturday","Sunday"},WEEKDAY($A32,2)) -> Tuesday | C32: Yes | D32: =COUNTIFS(Intentions!$B$2:$B$365,$A32) -> 3 | E32: =COUNTIFS(Intentions!$B$2:$B$365,$A32,Intentions!$H$2:$H$365,"<>Planned") -> 3 | F32: =COUNTIFS(Intentions!$B$2:$B$365,$A32,Intentions!$H$2:$H$365,"Done")+COUNTIFS(Intentions!$B$2:$B$365,$A32,Intentions!$H$2:$H$365,"Partial") -> 2 | G32: =IF(E32=0,"",SUMIFS(Intentions!$K$2:$K$365,Intentions!$B$2:$B$365,$A32)/E32) -> 0.66666667 | H32: =SUMIFS(Intentions!$G$2:$G$365,Intentions!$B$2:$B$365,$A32) -> 110 | I32: =SUMIFS(Activities!$F$2:$F$190,Activities!$B$2:$B$190,$A32) -> 88 | J32: =SUMIFS(Activities!$F$2:$F$190,Activities!$B$2:$B$190,$A32,Activities!$C$2:$C$190,"Spiritual") -> 0 | K32: =SUMIFS(Activities!$F$2:$F$190,Activities!$B$2:$B$190,$A32,Activities!$C$2:$C$190,"Physical") -> 0 | L32: =SUMIFS(Activities!$F$2:$F$190,Activities!$B$2:$B$190,$A32,Activities!$C$2:$C$190,"Studies") -> 70 | M32: =SUMIFS(Activities!$F$2:$F$190,Activities!$B$2:$B$190,$A32,Activities!$C$2:$C$190,"Professional") -> 0 | N32: =SUMIFS(Activities!$F$2:$F$190,Activities!$B$2:$B$190,$A32,Activities!$C$2:$C$190,"Personal") -> 0 | O32: =SUMIFS(Activities!$F$2:$F$190,Activities!$B$2:$B$190,$A32,Activities!$C$2:$C$190,"Relationships") -> 18 | P32: =SUMIFS(Activities!$F$2:$F$190,Activities!$B$2:$B$190,$A32,Activities!$C$2:$C$190,"Leisure and creativity") -> 0 | Q32: 8.4 | S32: 4 | T32: 4 | U32: 4 | V32: 3 | W32: 208 | X32: 8042 | Y32: 2.2 | Z32: =COUNTIFS(Reflections!$A$2:$A$70,$A32) -> 1 | AA32: Filled in the same day | AB32: 0
A33: 46253 | B33: =INDEX({"Monday","Tuesday","Wednesday","Thursday","Friday","Saturday","Sunday"},WEEKDAY($A33,2)) -> Wednesday | C33: Yes | D33: =COUNTIFS(Intentions!$B$2:$B$365,$A33) -> 2 | E33: =COUNTIFS(Intentions!$B$2:$B$365,$A33,Intentions!$H$2:$H$365,"<>Planned") -> 2 | F33: =COUNTIFS(Intentions!$B$2:$B$365,$A33,Intentions!$H$2:$H$365,"Done")+COUNTIFS(Intentions!$B$2:$B$365,$A33,Intentions!$H$2:$H$365,"Partial") -> 1 | G33: =IF(E33=0,"",SUMIFS(Intentions!$K$2:$K$365,Intentions!$B$2:$B$365,$A33)/E33) -> 0.5 | H33: =SUMIFS(Intentions!$G$2:$G$365,Intentions!$B$2:$B$365,$A33) -> 75 | I33: =SUMIFS(Activities!$F$2:$F$190,Activities!$B$2:$B$190,$A33) -> 16 | J33: =SUMIFS(Activities!$F$2:$F$190,Activities!$B$2:$B$190,$A33,Activities!$C$2:$C$190,"Spiritual") -> 16 | K33: =SUMIFS(Activities!$F$2:$F$190,Activities!$B$2:$B$190,$A33,Activities!$C$2:$C$190,"Physical") -> 0 | L33: =SUMIFS(Activities!$F$2:$F$190,Activities!$B$2:$B$190,$A33,Activities!$C$2:$C$190,"Studies") -> 0 | M33: =SUMIFS(Activities!$F$2:$F$190,Activities!$B$2:$B$190,$A33,Activities!$C$2:$C$190,"Professional") -> 0 | N33: =SUMIFS(Activities!$F$2:$F$190,Activities!$B$2:$B$190,$A33,Activities!$C$2:$C$190,"Personal") -> 0 | O33: =SUMIFS(Activities!$F$2:$F$190,Activities!$B$2:$B$190,$A33,Activities!$C$2:$C$190,"Relationships") -> 0 | P33: =SUMIFS(Activities!$F$2:$F$190,Activities!$B$2:$B$190,$A33,Activities!$C$2:$C$190,"Leisure and creativity") -> 0 | Q33: 7.6 | S33: 2 | T33: 1 | U33: 3 | V33: 3 | W33: 179 | X33: 4703 | Y33: 1.6 | Z33: =COUNTIFS(Reflections!$A$2:$A$70,$A33) -> 1 | AA33: Filled in the same day | AB33: 0
A34: 46254 | B34: =INDEX({"Monday","Tuesday","Wednesday","Thursday","Friday","Saturday","Sunday"},WEEKDAY($A34,2)) -> Thursday | C34: Yes | D34: =COUNTIFS(Intentions!$B$2:$B$365,$A34) -> 3 | E34: =COUNTIFS(Intentions!$B$2:$B$365,$A34,Intentions!$H$2:$H$365,"<>Planned") -> 3 | F34: =COUNTIFS(Intentions!$B$2:$B$365,$A34,Intentions!$H$2:$H$365,"Done")+COUNTIFS(Intentions!$B$2:$B$365,$A34,Intentions!$H$2:$H$365,"Partial") -> 1 | G34: =IF(E34=0,"",SUMIFS(Intentions!$K$2:$K$365,Intentions!$B$2:$B$365,$A34)/E34) -> 0.33333333 | H34: =SUMIFS(Intentions!$G$2:$G$365,Intentions!$B$2:$B$365,$A34) -> 135 | I34: =SUMIFS(Activities!$F$2:$F$190,Activities!$B$2:$B$190,$A34) -> 17 | J34: =SUMIFS(Activities!$F$2:$F$190,Activities!$B$2:$B$190,$A34,Activities!$C$2:$C$190,"Spiritual") -> 17 | K34: =SUMIFS(Activities!$F$2:$F$190,Activities!$B$2:$B$190,$A34,Activities!$C$2:$C$190,"Physical") -> 0 | L34: =SUMIFS(Activities!$F$2:$F$190,Activities!$B$2:$B$190,$A34,Activities!$C$2:$C$190,"Studies") -> 0 | M34: =SUMIFS(Activities!$F$2:$F$190,Activities!$B$2:$B$190,$A34,Activities!$C$2:$C$190,"Professional") -> 0 | N34: =SUMIFS(Activities!$F$2:$F$190,Activities!$B$2:$B$190,$A34,Activities!$C$2:$C$190,"Personal") -> 0 | O34: =SUMIFS(Activities!$F$2:$F$190,Activities!$B$2:$B$190,$A34,Activities!$C$2:$C$190,"Relationships") -> 0 | P34: =SUMIFS(Activities!$F$2:$F$190,Activities!$B$2:$B$190,$A34,Activities!$C$2:$C$190,"Leisure and creativity") -> 0 | Q34: 6.5 | S34: 3 | T34: 2 | U34: 3 | V34: 2 | W34: 208 | X34: 11382 | Y34: 2.3 | Z34: =COUNTIFS(Reflections!$A$2:$A$70,$A34) -> 1 | AA34: Filled in the same day | AB34: 0 | AC34: Projet Python présenté à des amis.
